Workbook

Sheet Data
A1: address | B1: addressLine1 | C1: addressLine2 | D1: agencyId | E1: agencyName | F1: agencyUrl | G1: agentName | H1: area | I1: buildYear | J1: city | K1: district | L1: friendlyId | M1: hasOpenBidding | N1: imageThumbnail | O1: imageUrls/0 | P1: imageUrls/1 | Q1: imageUrls/2 | R1: isNewBuilding | S1: isPrivateSeller | T1: latitude | U1: listingId | V1: listingUrl | W1: longitude | X1: price | Y1: priceFormatted | Z1: privateSellerName | AA1: propertySubtype | AB1: propertyType | AC1: publishedDate | AD1: roomCount | AE1: rooms | AF1: scrapedAt | AG1: title | AH1: totalArea | AI1: Type of Kitchen | AJ1: Sauna | AK1: Type of Outdoor Space | AL1: Type of bathrooms | AM1: Storage | AN1: Region
A2: Aakkulantie 27 Suorama Kangasala | B2: Aakkulantie 27 | C2: Suorama Kangasala | D2: 863 | E2: TA-Asumisoikeus Oy | F2: http://www.ta.fi/ | H2: 82.5 | I2: 2021 | J2: Kangasala | K2: Suorama | L2: fs3784 | M2: false | N2: https://d3ls91xgksobn.cloudfront.net/400x300/etuovimedia/images/property/import/818/2608818/0e76b9541118d347871c0e0e51d244c4/1a373497eae1485897c406bca4020db5/ORIGINAL.jpeg | O2: https://d3ls91xgksobn.cloudfront.net/1200x900/etuovimedia/images/property/import/818/2608818/0e76b9541118d347871c0e0e51d244c4/1a373497eae1485897c406bca4020db5/ORIGINAL.jpeg | R2: false | S2: false | T2: 61.4702 | U2: 2608818 | V2: https://www.etuovi.com/kohde/fs3784 | W2: 24.0108 | X2: 41378.85 | Y2: 41 378,85 € | AA2: Apartment (Kerrostalo) | AB2: RESIDENTIAL | AC2: 2026-06-10 | AD2: 4 | AE2: 4h + kt + s | AF2: 2026-06-10T14:04:21.678Z | AG2: Apartment (Kerrostalo) — 4h + kt + s — 82.5 m² — Suorama Kangasala | AI2: =IF(AE2="", "no info", IF(OR(ISNUMBER(SEARCH("kt", AE2)), ISNUMBER(SEARCH("avokeittiö", AE2))), "Open", IF(ISNUMBER(SEARCH("kk", AE2)), "Kitchenette", "Independent"))) -> Open | AJ2: =IF(AE2="", "no info", IF(OR(ISNUMBER(SEARCH(" s ", AE2)), ISNUMBER(SEARCH("sauna", AE2)), ISNUMBER(SEARCH("+ s", AE2))), "YES", "NO")) -> YES | AK2: =IF(AE2="", "no info", IF(OR(ISNUMBER(SEARCH("las.p", AE2)), ISNUMBER(SEARCH("lasitettu", AE2))), "Glazed Balcony", IF(OR(ISNUMBER(SEARCH(" p ", AE2)), ISNUMBER(SEARCH("parveke", AE2))), "Standard Balcony", IF(OR(ISNUMBER(SEARCH("terassi", AE2)), ISNUMBER(SEARCH("kuisti", AE2))), "Terrace", "None")))) -> None | AL2: =IF(AE2="", "no info", IF(OR(ISNUMBER(SEARCH("2wc", AE2)), ISNUMBER(SEARCH("2xwc", AE2))), "2 Toilets", "1 Toilet")) -> 1 Toilet | AM2: =IF(AE2="", "no info", IF(OR(ISNUMBER(SEARCH("vh", AE2)), ISNUMBER(SEARCH("var", AE2))), "YES", "NO")) -> NO | AN2: =VLOOKUP(J2, 'Regions and Cities'!A:B, 2, FALSE) -> Pirkanmaa
A3: Aapelinkatu 13 Matinkylä Espoo | B3: Aapelinkatu 13 | C3: Matinkylä Espoo | D3: 3439 | E3: Kiinteistömaailma Espoo Matinkylä, Kauppakeskus Iso Omena | Adream Espoon Kodit Oy | F3: http://www.kiinteistomaailma.fi/ | H3: 45 | I3: 1971 | J3: Espoo | K3: Matinkylä | L3: 67108371 | M3: false | N3: https://d3ls91xgksobn.cloudfront.net/400x300/etuovimedia/images/property/import/470/2608470/0e76b9541118d347871c0e0e51d244c4/3f8ec8cd2debccb65d2813f77dd59262/ORIGINAL.jpeg | O3: https://d3ls91xgksobn.cloudfront.net/1200x900/etuovimedia/images/property/import/470/2608470/0e76b9541118d347871c0e0e51d244c4/3f8ec8cd2debccb65d2813f77dd59262/ORIGINAL.jpeg | R3: false | S3: false | T3: 60.155131 | U3: 2608470 | V3: https://www.etuovi.com/kohde/67108371 | W3: 24.746499 | X3: 149000 | Y3: 149 000 € | AA3: Apartment (Kerrostalo) | AB3: RESIDENTIAL | AC3: 2026-06-09 | AD3: 2 | AE3: 2h + kk | AF3: 2026-06-10T14:04:45.807Z | AG3: Apartment (Kerrostalo) — 2h + kk — 45 m² — Matinkylä Espoo | AH3: 45 | AI3: =IF(AE3="", "no info", IF(OR(ISNUMBER(SEARCH("kt", AE3)), ISNUMBER(SEARCH("avokeittiö", AE3))), "Open", IF(ISNUMBER(SEARCH("kk", AE3)), "Kitchenette", "Independent"))) -> Kitchenette | AJ3: =IF(AE3="", "no info", IF(OR(ISNUMBER(SEARCH(" s ", AE3)), ISNUMBER(SEARCH("sauna", AE3)), ISNUMBER(SEARCH("+ s", AE3))), "YES", "NO")) -> NO | AK3: =IF(AE3="", "no info", IF(OR(ISNUMBER(SEARCH("las.p", AE3)), ISNUMBER(SEARCH("lasitettu", AE3))), "Glazed Balcony", IF(OR(ISNUMBER(SEARCH(" p ", AE3)), ISNUMBER(SEARCH("parveke", AE3))), "Standard Balcony", IF(OR(ISNUMBER(SEARCH("terassi", AE3)), ISNUMBER(SEARCH("kuisti", AE3))), "Terrace", "None")))) -> None | AL3: =IF(AE3="", "no info", IF(OR(ISNUMBER(SEARCH("2wc", AE3)), ISNUMBER(SEARCH("2xwc", AE3))), "2 Toilets", "1 Toilet")) -> 1 Toilet | AM3: =IF(AE3="", "no info", IF(OR(ISNUMBER(SEARCH("vh", AE3)), ISNUMBER(SEARCH("var", AE3))), "YES", "NO")) -> NO | AN3: =VLOOKUP(J3, 'Regions and Cities'!A:B, 2, FALSE) -> Uusimaa
A4: Ahjolankatu 26 Petsamo Riihimäki | B4: Ahjolankatu 26 | C4: Petsamo Riihimäki | D4: 4635 | E4: Aitoasunnot Riihimäki | Palhomaa Oy | F4: http://aitoasunnot.fi/ | G4: Marja Malin | H4: 195 | I4: 1967 | J4: Riihimäki | K4: Petsamo | L4: 49637842 | M4: false | N4: https://d3ls91xgksobn.cloudfront.net/400x300/etuovimedia/images/property/import/525/2609525/0e76b9541118d347871c0e0e51d244c4/225ba1e6287b98d7148a91db03dbdeb0/ORIGINAL.jpeg | O4: https://d3ls91xgksobn.cloudfront.net/1200x900/etuovimedia/images/property/import/525/2609525/0e76b9541118d347871c0e0e51d244c4/225ba1e6287b98d7148a91db03dbdeb0/ORIGINAL.jpeg | P4: https://d3ls91xgksobn.cloudfront.net/1200x900/etuovimedia/images/property/import/525/2609525/0e76b9541118d347871c0e0e51d244c4/85b93f049e4210f717499cc7f3c07577/ORIGINAL.jpeg | R4: false | S4: false | T4: 60.74955 | U4: 2609525 | V4: https://www.etuovi.com/kohde/49637842 | W4: 24.780109 | X4: 229000 | Y4: 229 000 € | AA4: Detached House (Omakotitalo) | AB4: RESIDENTIAL | AC4: 2026-06-10 | AD4: 5 | AE4: 5h + k ja 2h + k sekä autotalli ja katettu terassi. | AF4: 2026-06-10T14:03:16.072Z | AG4: Detached House (Omakotitalo) — 5h + k ja 2h + k sekä autotalli ja katettu terassi. — 195 m² — Petsamo Riihimäki | AH4: 287 | AI4: =IF(AE4="", "no info", IF(OR(ISNUMBER(SEARCH("kt", AE4)), ISNUMBER(SEARCH("avokeittiö", AE4))), "Open", IF(ISNUMBER(SEARCH("kk", AE4)), "Kitchenette", "Independent"))) -> Independent | AJ4: =IF(AE4="", "no info", IF(OR(ISNUMBER(SEARCH(" s ", AE4)), ISNUMBER(SEARCH("sauna", AE4)), ISNUMBER(SEARCH("+ s", AE4))), "YES", "NO")) -> NO | AK4: =IF(AE4="", "no info", IF(OR(ISNUMBER(SEARCH("las.p", AE4)), ISNUMBER(SEARCH("lasitettu", AE4))), "Glazed Balcony", IF(OR(ISNUMBER(SEARCH(" p ", AE4)), ISNUMBER(SEARCH("parveke", AE4))), "Standard Balcony", IF(OR(ISNUMBER(SEARCH("terassi", AE4)), ISNUMBER(SEARCH("kuisti", AE4))), "Terrace", "None")))) -> Terrace | AL4: =IF(AE4="", "no info", IF(OR(ISNUMBER(SEARCH("2wc", AE4)), ISNUMBER(SEARCH("2xwc", AE4))), "2 Toilets", "1 Toilet")) -> 1 Toilet | AM4: =IF(AE4="", "no info", IF(OR(ISNUMBER(SEARCH("vh", AE4)), ISNUMBER(SEARCH("var", AE4))), "YES", "NO")) -> NO | AN4: =VLOOKUP(J4, 'Regions and Cities'!A:B, 2, FALSE) -> Kanta-Häme
A5: Ahjotie 10 Lammi Hämeenlinna | B5: Ahjotie 10 | C5: Lammi Hämeenlinna | D5: 279 | E5: Hämeenlinnan Kotijoukkue Oy | F5: http://www.kotijoukkue.fi/ | H5: 130 | I5: 1990 | J5: Hämeenlinna | K5: Lammi | L5: 20730711 | M5: false | N5: https://d3ls91xgksobn.cloudfront.net/400x300/etuovimedia/images/property/import/605/2609605/0e76b9541118d347871c0e0e51d244c4/1078fbade922c3259017f0efe0d7aec1/ORIGINAL.jpeg | O5: https://d3ls91xgksobn.cloudfront.net/1200x900/etuovimedia/images/property/import/605/2609605/0e76b9541118d347871c0e0e51d244c4/1078fbade922c3259017f0efe0d7aec1/ORIGINAL.jpeg | R5: false | S5: false | T5: 61.072645 | U5: 2609605 | V5: https://www.etuovi.com/kohde/20730711 | W5: 25.000999 | X5: 159000 | Y5: 159 000 € | AA5: Detached House (Omakotitalo) | AB5: RESIDENTIAL | AC5: 2026-06-10 | AD5: 5 | AE5: 5H + K + PSH / WC + S + KHH + WC + VH + Ullakko + Kat.ter. + ET + Tuulik.Var. + AT | AF5: 2026-06-10T14:03:06.264Z | AG5: Detached House (Omakotitalo) — 5H + K + PSH / WC + S + KHH + WC + VH + Ullakko + Kat.ter. + ET + Tuulik.Var. + AT — 130 m² — Lammi Hämeenlinna | AH5: 175 | AI5: =IF(AE5="", "no info", IF(OR(ISNUMBER(SEARCH("kt", AE5)), ISNUMBER(SEARCH("avokeittiö", AE5))), "Open", IF(ISNUMBER(SEARCH("kk", AE5)), "Kitchenette", "Independent"))) -> Kitchenette | AJ5: =IF(AE5="", "no info", IF(OR(ISNUMBER(SEARCH(" s ", AE5)), ISNUMBER(SEARCH("sauna", AE5)), ISNUMBER(SEARCH("+ s", AE5))), "YES", "NO")) -> YES | AK5: =IF(AE5="", "no info", IF(OR(ISNUMBER(SEARCH("las.p", AE5)), ISNUMBER(SEARCH("lasitettu", AE5))), "Glazed Balcony", IF(OR(ISNUMBER(SEARCH(" p ", AE5)), ISNUMBER(SEARCH("parveke", AE5))), "Standard Balcony", IF(OR(ISNUMBER(SEARCH("terassi", AE5)), ISNUMBER(SEARCH("kuisti", AE5))), "Terrace", "None")))) -> None | AL5: =IF(AE5="", "no info", IF(OR(ISNUMBER(SEARCH("2wc", AE5)), ISNUMBER(SEARCH("2xwc", AE5))), "2 Toilets", "1 Toilet")) -> 1 Toilet | AM5: =IF(AE5="", "no info", IF(OR(ISNUMBER(SEARCH("vh", AE5)), ISNUMBER(SEARCH("var", AE5))), "YES", "NO")) -> YES | AN5: =VLOOKUP(J5, 'Regions and Cities'!A:B, 2, FALSE) -> Kanta-Häme
A6: Ahomansikantie 18 Rantakylä Joensuu | B6: Ahomansikantie 18 | C6: Rantakylä Joensuu | D6: 1082 | E6: Kiinteistömaailma Joensuu | Kotipysäkki Oy | F6: http://www.kiinteistomaailma.fi/ | G6: Niina Savolainen | H6: 128 | I6: 2007 | J6: Joensuu | K6: Rantakylä | L6: 66496812 | M6: false | N6: https://d3ls91xgksobn.cloudfront.net/400x300/etuovimedia/images/property/import/498/2609498/0e76b9541118d347871c0e0e51d244c4/e82c758566d25167ce5f17881eff588f/ORIGINAL.jpeg | O6: https://d3ls91xgksobn.cloudfront.net/1200x900/etuovimedia/images/property/import/498/2609498/0e76b9541118d347871c0e0e51d244c4/e82c758566d25167ce5f17881eff588f/ORIGINAL.jpeg | P6: https://d3ls91xgksobn.cloudfront.net/1200x900/etuovimedia/images/property/import/498/2609498/0e76b9541118d347871c0e0e51d244c4/b37d64f163dc9831ccb0ed8372db0974/ORIGINAL.jpeg | R6: false | S6: false | T6: 62.625845 | U6: 2609498 | V6: https://www.etuovi.com/kohde/66496812 | W6: 29.832986 | X6: 249000 | Y6: 249 000 € | AA6: Detached House (Omakotitalo) | AB6: RESIDENTIAL | AC6: 2026-06-10 | AD6: 4 | AE6: 4h, k, khh, kph, autokatos | AF6: 2026-06-10T14:03:19.416Z | AG6: Detached House (Omakotitalo) — 4h, k, khh, kph, autokatos — 128 m² — Rantakylä Joensuu | AH6: 163 | AI6: =IF(AE6="", "no info", IF(OR(ISNUMBER(SEARCH("kt", AE6)), ISNUMBER(SEARCH("avokeittiö", AE6))), "Open", IF(ISNUMBER(SEARCH("kk", AE6)), "Kitchenette", "Independent"))) -> Independent | AJ6: =IF(AE6="", "no info", IF(OR(ISNUMBER(SEARCH(" s ", AE6)), ISNUMBER(SEARCH("sauna", AE6)), ISNUMBER(SEARCH("+ s", AE6))), "YES", "NO")) -> NO | AK6: =IF(AE6="", "no info", IF(OR(ISNUMBER(SEARCH("las.p", AE6)), ISNUMBER(SEARCH("lasitettu", AE6))), "Glazed Balcony", IF(OR(ISNUMBER(SEARCH(" p ", AE6)), ISNUMBER(SEARCH("parveke", AE6))), "Standard Balcony", IF(OR(ISNUMBER(SEARCH("terassi", AE6)), ISNUMBER(SEARCH("kuisti", AE6))), "Terrace", "None")))) -> None | AL6: =IF(AE6="", "no info", IF(OR(ISNUMBER(SEARCH("2wc", AE6)), ISNUMBER(SEARCH("2xwc", AE6))), "2 Toilets", "1 Toilet")) -> 1 Toilet | AM6: =IF(AE6="", "no info", IF(OR(ISNUMBER(SEARCH("vh", AE6)), ISNUMBER(SEARCH("var", AE6))), "YES", "NO")) -> NO | AN6: =VLOOKUP(J6, 'Regions and Cities'!A:B, 2, FALSE) -> Pohjois-Karjala
A7: Ahorannantie 22 as Kellarpelto Savonlinna | B7: Ahorannantie 22 as | C7: Kellarpelto Savonlinna | D7: 3064 | E7: OP Koti Itä-Suomi Oy LKV, Savonlinna | F7: https://op-koti.fi?cmpid=.opkoti..huom.1.etuovi.banner.yrityslogo.ha_jn_opkoti_valitys | G7: Liisa Hiltunen | H7: 187 | I7: 1974 | J7: Savonlinna | K7: Kellarpelto | L7: 620840 | M7: false | N7: https://d3ls91xgksobn.cloudfront.net/400x300/etuovimedia/images/property/import/414/2608414/0e76b9541118d347871c0e0e51d244c4/bfb077e649a04d08c36930f071761110/ORIGINAL.jpeg | O7: https://d3ls91xgksobn.cloudfront.net/1200x900/etuovimedia/images/property/import/414/2608414/0e76b9541118d347871c0e0e51d244c4/bfb077e649a04d08c36930f071761110/ORIGINAL.jpeg | P7: https://d3ls91xgksobn.cloudfront.net/1200x900/etuovimedia/images/property/import/414/2608414/0e76b9541118d347871c0e0e51d244c4/088c851924db8ece2cd2f217bbb8dc4d/ORIGINAL.jpeg | R7: false | S7: false | T7: 61.885363 | U7: 2608414 | V7: https://www.etuovi.com/kohde/620840 | W7: 28.801368 | X7: 65000 | Y7: 65 000 € | AA7: Semi-detached (Paritalo) | AB7: RESIDENTIAL | AC7: 2026-06-09 | AD7: 3 | AE7: 3h, k, s | AF7: 2026-06-10T14:04:49.344Z | AG7: Semi-detached (Paritalo) — 3h, k, s — 187 m² — Kellarpelto Savonlinna | AH7: 187 | AI7: =IF(AE7="", "no info", IF(OR(ISNUMBER(SEARCH("kt", AE7)), ISNUMBER(SEARCH("avokeittiö", AE7))), "Open", IF(ISNUMBER(SEARCH("kk", AE7)), "Kitchenette", "Independent"))) -> Independent | AJ7: =IF(AE7="", "no info", IF(OR(ISNUMBER(SEARCH(" s ", AE7)), ISNUMBER(SEARCH("sauna", AE7)), ISNUMBER(SEARCH("+ s", AE7))), "YES", "NO")) -> NO | AK7: =IF(AE7="", "no info", IF(OR(ISNUMBER(SEARCH("las.p", AE7)), ISNUMBER(SEARCH("lasitettu", AE7))), "Glazed Balcony", IF(OR(ISNUMBER(SEARCH(" p ", AE7)), ISNUMBER(SEARCH("parveke", AE7))), "Standard Balcony", IF(OR(ISNUMBER(SEARCH("terassi", AE7)), ISNUMBER(SEARCH("kuisti", AE7))), "Terrace", "None")))) -> None | AL7: =IF(AE7="", "no info", IF(OR(ISNUMBER(SEARCH("2wc", AE7)), ISNUMBER(SEARCH("2xwc", AE7))), "2 Toilets", "1 Toilet")) -> 1 Toilet | AM7: =IF(AE7="", "no info", IF(OR(ISNUMBER(SEARCH("vh", AE7)), ISNUMBER(SEARCH("var", AE7))), "YES", "NO")) -> NO | AN7: =VLOOKUP(J7, 'Regions and Cities'!A:B, 2, FALSE) -> Etelä-Savo
A8: Ähtäväntie 232 Ähtävä Pedersören kunta | B8: Ähtäväntie 232 | C8: Ähtävä Pedersören kunta | D8: 2028 | E8: Ab Mäklarbyrå J. Riska Meklaritoimisto Oy | F8: http://www.riska.fi | H8: 151 | I8: 1934 | J8: Esse | K8: Ähtävä Pedersören | L8: 21222446 | M8: false | N8: https://d3ls91xgksobn.cloudfront.net/400x300/etuovimedia/images/property/import/254/2609254/0e76b9541118d347871c0e0e51d244c4/54624629609f2d2fd26e79d944112a14/ORIGINAL.jpeg | O8: https://d3ls91xgksobn.cloudfront.net/1200x900/etuovimedia/images/property/import/254/2609254/0e76b9541118d347871c0e0e51d244c4/54624629609f2d2fd26e79d944112a14/ORIGINAL.jpeg | R8: false | S8: false | T8: 63.584459 | U8: 2609254 | V8: https://www.etuovi.com/kohde/21222446 | W8: 23.088831 | X8: 85000 | Y8: 85 000 € | AA8: Detached House (Omakotitalo) | AB8: RESIDENTIAL | AC8: 2026-06-10 | AD8: 5+ | AE8: 7-8 h + k + kph + wc + kellari | AF8: 2026-06-10T14:03:40.851Z | AG8: Detached House (Omakotitalo) — 7-8 h + k + kph + wc + kellari — 151 m² — Ähtävä Pedersören kunta | AH8: 200 | AI8: =IF(AE8="", "no info", IF(OR(ISNUMBER(SEARCH("kt", AE8)), ISNUMBER(SEARCH("avokeittiö", AE8))), "Open", IF(ISNUMBER(SEARCH("kk", AE8)), "Kitchenette", "Independent"))) -> Independent | AJ8: =IF(AE8="", "no info", IF(OR(ISNUMBER(SEARCH(" s ", AE8)), ISNUMBER(SEARCH("sauna", AE8)), ISNUMBER(SEARCH("+ s", AE8))), "YES", "NO")) -> NO | AK8: =IF(AE8="", "no info", IF(OR(ISNUMBER(SEARCH("las.p", AE8)), ISNUMBER(SEARCH("lasitettu", AE8))), "Glazed Balcony", IF(OR(ISNUMBER(SEARCH(" p ", AE8)), ISNUMBER(SEARCH("parveke", AE8))), "Standard Balcony", IF(OR(ISNUMBER(SEARCH("terassi", AE8)), ISNUMBER(SEARCH("kuisti", AE8))), "Terrace", "None")))) -> None | AL8: =IF(AE8="", "no info", IF(OR(ISNUMBER(SEARCH("2wc", AE8)), ISNUMBER(SEARCH("2xwc", AE8))), "2 Toilets", "1 Toilet")) -> 1 Toilet | AM8: =IF(AE8="", "no info", IF(OR(ISNUMBER(SEARCH("vh", AE8)), ISNUMBER(SEARCH("var", AE8))), "YES", "NO")) -> NO | AN8: =VLOOKUP(J8, 'Regions and Cities'!A:B, 2, FALSE) -> Pohjanmaa
A9: Ahvenkoskentie 15 Ahvenkoski Loviisa | B9: Ahvenkoskentie 15 | C9: Ahvenkoski Loviisa | D9: 215 | E9: Aktia Kiinteistönvälitys Oy, Loviisa, Aktia Fastighetsförmedling Ab, Lovisa | F9: https://www.aktialkv.fi/ | H9: 110 | I9: 1950 | J9: Loviisa | K9: Ahvenkoski | L9: 21556033 | M9: false | N9: https://d3ls91xgksobn.cloudfront.net/400x300/etuovimedia/images/property/import/406/2609406/0e76b9541118d347871c0e0e51d244c4/457639f0183e2dc91228b1bffae69529/ORIGINAL.jpeg | O9: https://d3ls91xgksobn.cloudfront.net/1200x900/etuovimedia/images/property/import/406/2609406/0e76b9541118d347871c0e0e51d244c4/457639f0183e2dc91228b1bffae69529/ORIGINAL.jpeg | R9: false | S9: false | T9: 60.498602 | U9: 2609406 | V9: https://www.etuovi.com/kohde/21556033 | W9: 26.440602 | X9: 59000 | Y9: 59 000 € | AA9: Detached House (Omakotitalo) | AB9: RESIDENTIAL | AC9: 2026-06-10 | AD9: 4 | AE9: 4h + k + s | AF9: 2026-06-10T14:03:27.575Z | AG9: Detached House (Omakotitalo) — 4h + k + s — 110 m² — Ahvenkoski Loviisa | AH9: 136 | AI9: =IF(AE9="", "no info", IF(OR(ISNUMBER(SEARCH("kt", AE9)), ISNUMBER(SEARCH("avokeittiö", AE9))), "Open", IF(ISNUMBER(SEARCH("kk", AE9)), "Kitchenette", "Independent"))) -> Independent | AJ9: =IF(AE9="", "no info", IF(OR(ISNUMBER(SEARCH(" s ", AE9)), ISNUMBER(SEARCH("sauna", AE9)), ISNUMBER(SEARCH("+ s", AE9))), "YES", "NO")) -> YES | AK9: =IF(AE9="", "no info", IF(OR(ISNUMBER(SEARCH("las.p", AE9)), ISNUMBER(SEARCH("lasitettu", AE9))), "Glazed Balcony", IF(OR(ISNUMBER(SEARCH(" p ", AE9)), ISNUMBER(SEARCH("parveke", AE9))), "Standard Balcony", IF(OR(ISNUMBER(SEARCH("terassi", AE9)), ISNUMBER(SEARCH("kuisti", AE9))), "Terrace", "None")))) -> None | AL9: =IF(AE9="", "no info", IF(OR(ISNUMBER(SEARCH("2wc", AE9)), ISNUMBER(SEARCH("2xwc", AE9))), "2 Toilets", "1 Toilet")) -> 1 Toilet | AM9: =IF(AE9="", "no info", IF(OR(ISNUMBER(SEARCH("vh", AE9)), ISNUMBER(SEARCH("var", AE9))), "YES", "NO")) -> NO | AN9: =VLOOKUP(J9, 'Regions and Cities'!A:B, 2, FALSE) -> Uusimaa
A10: Ahventie 17 Pyykösjärvi Oulu | B10: Ahventie 17 | C10: Pyykösjärvi Oulu | D10: 2930 | E10: Toivo LKV Oy | H10: 112 | I10: 1970 | J10: Oulu | K10: Pyykösjärvi | L10: 21431769 | M10: false | N10: https://d3ls91xgksobn.cloudfront.net/400x300/etuovimedia/images/property/import/608/2609608/0e76b9541118d347871c0e0e51d244c4/e9db8d9d94d57edfbb9eb30d0a5262c9/ORIGINAL.jpeg | O10: https://d3ls91xgksobn.cloudfront.net/1200x900/etuovimedia/images/property/import/608/2609608/0e76b9541118d347871c0e0e51d244c4/e9db8d9d94d57edfbb9eb30d0a5262c9/ORIGINAL.jpeg | R10: false | S10: false | T10: 65.044659 | U10: 2609608 | V10: https://www.etuovi.com/kohde/21431769 | W10: 25.496587 | X10: 155000 | Y10: 155 000 € | AA10: Row House (Rivitalo) | AB10: RESIDENTIAL | AC10: 2026-06-10 | AD10: 5 | AE10: 5 h + k + kh + s | AF10: 2026-06-10T14:03:06.155Z | AG10: Row House (Rivitalo) — 5 h + k + kh + s — 112 m² — Pyykösjärvi Oulu | AH10: 112 | AI10: =IF(AE10="", "no info", IF(OR(ISNUMBER(SEARCH("kt", AE10)), ISNUMBER(SEARCH("avokeittiö", AE10))), "Open", IF(ISNUMBER(SEARCH("kk", AE10)), "Kitchenette", "Independent"))) -> Independent | AJ10: =IF(AE10="", "no info", IF(OR(ISNUMBER(SEARCH(" s ", AE10)), ISNUMBER(SEARCH("sauna", AE10)), ISNUMBER(SEARCH("+ s", AE10))), "YES", "NO")) -> YES | AK10: =IF(AE10="", "no info", IF(OR(ISNUMBER(SEARCH("las.p", AE10)), ISNUMBER(SEARCH("lasitettu", AE10))), "Glazed Balcony", IF(OR(ISNUMBER(SEARCH(" p ", AE10)), ISNUMBER(SEARCH("parveke", AE10))), "Standard Balcony", IF(OR(ISNUMBER(SEARCH("terassi", AE10)), ISNUMBER(SEARCH("kuisti", AE10))), "Terrace", "None")))) -> None | AL10: =IF(AE10="", "no info", IF(OR(ISNUMBER(SEARCH("2wc", AE10)), ISNUMBER(SEARCH("2xwc", AE10))), "2 Toilets", "1 Toilet")) -> 1 Toilet | AM10: =IF(AE10="", "no info", IF(OR(ISNUMBER(SEARCH("vh", AE10)), ISNUMBER(SEARCH("var", AE10))), "YES", "NO")) -> NO | AN10: =VLOOKUP(J10, 'Regions and Cities'!A:B, 2, FALSE) -> Pohjois-Pohjanmaa
A11: Ailakinkatu 18 A Tourula Jyväskylä | B11: Ailakinkatu 18 A | C11: Tourula Jyväskylä | D11: 4612 | E11: OP Koti Sisä-Suomi Oy LKV, Jyväskylä Taulumäki | F11: https://op-koti.fi?cmpid=.opkoti..huom.1.etuovi.banner.yrityslogo.ha_jn_opkoti_valitys | G11: Hannele Aro | H11: 85 | I11: 1990 | J11: Jyväskylä | K11: Tourula | L11: 620039 | M11: false | N11: https://d3ls91xgksobn.cloudfront.net/400x300/etuovimedia/images/property/import/645/2608645/0e76b9541118d347871c0e0e51d244c4/456071eb15334c702126b3804f88c0e8/ORIGINAL.jpeg | O11: https://d3ls91xgksobn.cloudfront.net/1200x900/etuovimedia/images/property/import/645/2608645/0e76b9541118d347871c0e0e51d244c4/456071eb15334c702126b3804f88c0e8/ORIGINAL.jpeg | P11: https://d3ls91xgksobn.cloudfront.net/1200x900/etuovimedia/images/property/import/645/2608645/0e76b9541118d347871c0e0e51d244c4/22b8656cf1a848930c072d1d5b37f669/ORIGINAL.jpeg | R11: false | S11: false | T11: 62.248954 | U11: 2608645 | V11: https://www.etuovi.com/kohde/620039 | W11: 25.755734 | X11: 165000 | Y11: 165 000 € | AA11: Apartment (Kerrostalo) | AB11: RESIDENTIAL | AC11: 2026-06-09 | AD11: 4 | AE11: 4h, k, kh, s, erill.wc, lasit.p. | AF11: 2026-06-10T14:04:28.478Z | AG11: Apartment (Kerrostalo) — 4h, k, kh, s, erill.wc, lasit.p. — 85 m² — Tourula Jyväskylä | AH11: 85 | AI11: =IF(AE11="", "no info", IF(OR(ISNUMBER(SEARCH("kt", AE11)), ISNUMBER(SEARCH("avokeittiö", AE11))), "Open", IF(ISNUMBER(SEARCH("kk", AE11)), "Kitchenette", "Independent"))) -> Independent | AJ11: =IF(AE11="", "no info", IF(OR(ISNUMBER(SEARCH(" s ", AE11)), ISNUMBER(SEARCH("sauna", AE11)), ISNUMBER(SEARCH("+ s", AE11))), "YES", "NO")) -> NO | AK11: =IF(AE11="", "no info", IF(OR(ISNUMBER(SEARCH("las.p", AE11)), ISNUMBER(SEARCH("lasitettu", AE11))), "Glazed Balcony", IF(OR(ISNUMBER(SEARCH(" p ", AE11)), ISNUMBER(SEARCH("parveke", AE11))), "Standard Balcony", IF(OR(ISNUMBER(SEARCH("terassi", AE11)), ISNUMBER(SEARCH("kuisti", AE11))), "Terrace", "None")))) -> None | AL11: =IF(AE11="", "no info", IF(OR(ISNUMBER(SEARCH("2wc", AE11)), ISNUMBER(SEARCH("2xwc", AE11))), "2 Toilets", "1 Toilet")) -> 1 Toilet | AM11: =IF(AE11="", "no info", IF(OR(ISNUMBER(SEARCH("vh", AE11)), ISNUMBER(SEARCH("var", AE11))), "YES", "NO")) -> NO | AN11: =VLOOKUP(J11, 'Regions and Cities'!A:B, 2, FALSE) -> Keski-Suomi
A12: Aittatie 6b Konala Helsinki | B12: Aittatie 6b | C12: Konala Helsinki | D12: 1202 | E12: Kiinteistömaailma Helsinki Kallio-Kalasatama | Kallion Kodit Oy | F12: http://www.kiinteistomaailma.fi/ | H12: 142 | I12: 2007 | J12: Helsinki | K12: Konala | L12: 62764927 | M12: false | N12: https://d3ls91xgksobn.cloudfront.net/400x300/etuovimedia/images/property/import/510/2608510/0e76b9541118d347871c0e0e51d244c4/5bede7d52b2398b74851d8eb54509731/ORIGINAL.jpeg | O12: https://d3ls91xgksobn.cloudfront.net/1200x900/etuovimedia/images/property/import/510/2608510/0e76b9541118d347871c0e0e51d244c4/5bede7d52b2398b74851d8eb54509731/ORIGINAL.jpeg | R12: false | S12: false | T12: 60.234647 | U12: 2608510 | V12: https://www.etuovi.com/kohde/62764927 | W12: 24.845282 | X12: 468000 | Y12: 468 000 € | AA12: Semi-detached (Paritalo) | AB12: RESIDENTIAL | AC12: 2026-06-09 | AD12: 5 | AE12: 5h, avok, 2xkph, s, khh | AF12: 2026-06-10T14:04:43.014Z | AG12: Semi-detached (Paritalo) — 5h, avok, 2xkph, s, khh — 142 m² — Konala Helsinki | AI12: =IF(AE12="", "no info", IF(OR(ISNUMBER(SEARCH("kt", AE12)), ISNUMBER(SEARCH("avokeittiö", AE12))), "Open", IF(ISNUMBER(SEARCH("kk", AE12)), "Kitchenette", "Independent"))) -> Independent | AJ12: =IF(AE12="", "no info", IF(OR(ISNUMBER(SEARCH(" s ", AE12)), ISNUMBER(SEARCH("sauna", AE12)), ISNUMBER(SEARCH("+ s", AE12))), "YES", "NO")) -> NO | AK12: =IF(AE12="", "no info", IF(OR(ISNUMBER(SEARCH("las.p", AE12)), ISNUMBER(SEARCH("lasitettu", AE12))), "Glazed Balcony", IF(OR(ISNUMBER(SEARCH(" p ", AE12)), ISNUMBER(SEARCH("parveke", AE12))), "Standard Balcony", IF(OR(ISNUMBER(SEARCH("terassi", AE12)), ISNUMBER(SEARCH("kuisti", AE12))), "Terrace", "None")))) -> None | AL12: =IF(AE12="", "no info", IF(OR(ISNUMBER(SEARCH("2wc", AE12)), ISNUMBER(SEARCH("2xwc", AE12))), "2 Toilets", "1 Toilet")) -> 1 Toilet | AM12: =IF(AE12="", "no info", IF(OR(ISNUMBER(SEARCH("vh", AE12)), ISNUMBER(SEARCH("var", AE12))), "YES", "NO")) -> NO | AN12: =VLOOKUP(J12, 'Regions and Cities'!A:B, 2, FALSE) -> Uusimaa
A13: Ajojahdintie 18 Lippajärvi Espoo | B13: Ajojahdintie 18 | C13: Lippajärvi Espoo | D13: 2017 | E13: House Company LKV Oy | H13: 80 | I13: 1976 | J13: Espoo | K13: Lippajärvi | L13: 20206332 | M13: false | N13: https://d3ls91xgksobn.cloudfront.net/400x300/etuovimedia/images/property/import/647/2608647/0e76b9541118d347871c0e0e51d244c4/1e68719dde7339ede693517f26e99ffb/ORIGINAL.jpeg | O13: https://d3ls91xgksobn.cloudfront.net/1200x900/etuovimedia/images/property/import/647/2608647/0e76b9541118d347871c0e0e51d244c4/1e68719dde7339ede693517f26e99ffb/ORIGINAL.jpeg | R13: false | S13: false | T13: 60.230597 | U13: 2608647 | V13: https://www.etuovi.com/kohde/20206332 | W13: 24.713928 | X13: 259000 | Y13: 259 000 € | AA13: Row House (Rivitalo) | AB13: RESIDENTIAL | AC13: 2026-06-09 | AD13: 3 | AE13: 3h + k + kph + s | AF13: 2026-06-10T14:04:28.451Z | AG13: Row House (Rivitalo) — 3h + k + kph + s — 80 m² — Lippajärvi Espoo | AH13: 80 | AI13: =IF(AE13="", "no info", IF(OR(ISNUMBER(SEARCH("kt", AE13)), ISNUMBER(SEARCH("avokeittiö", AE13))), "Open", IF(ISNUMBER(SEARCH("kk", AE13)), "Kitchenette", "Independent"))) -> Independent | AJ13: =IF(AE13="", "no info", IF(OR(ISNUMBER(SEARCH(" s ", AE13)), ISNUMBER(SEARCH("sauna", AE13)), ISNUMBER(SEARCH("+ s", AE13))), "YES", "NO")) -> YES | AK13: =IF(AE13="", "no info", IF(OR(ISNUMBER(SEARCH("las.p", AE13)), ISNUMBER(SEARCH("lasitettu", AE13))), "Glazed Balcony", IF(OR(ISNUMBER(SEARCH(" p ", AE13)), ISNUMBER(SEARCH("parveke", AE13))), "Standard Balcony", IF(OR(ISNUMBER(SEARCH("terassi", AE13)), ISNUMBER(SEARCH("kuisti", AE13))), "Terrace", "None")))) -> None | AL13: =IF(AE13="", "no info", IF(OR(ISNUMBER(SEARCH("2wc", AE13)), ISNUMBER(SEARCH("2xwc", AE13))), "2 Toilets", "1 Toilet")) -> 1 Toilet | AM13: =IF(AE13="", "no info", IF(OR(ISNUMBER(SEARCH("vh", AE13)), ISNUMBER(SEARCH("var", AE13))), "YES", "NO")) -> NO | AN13: =VLOOKUP(J13, 'Regions and Cities'!A:B, 2, FALSE) -> Uusimaa
A14: Ajurinkatu 4 B Kirjavatolppa Hyvinkää | B14: Ajurinkatu 4 B | C14: Kirjavatolppa Hyvinkää | D14: 83 | E14: Huoneistokeskus Hyvinkää | F14: https://www.huoneistokeskus.fi/ | H14: 42 | I14: 1971 | J14: Hyvinkää | K14: Kirjavatolppa | L14: 80505512 | M14: false | N14: https://d3ls91xgksobn.cloudfront.net/400x300/etuovimedia/images/property/import/539/2609539/0e76b9541118d347871c0e0e51d244c4/388d88b8f2d0b8749f032c021dd8647d/ORIGINAL.jpeg | O14: https://d3ls91xgksobn.cloudfront.net/1200x900/etuovimedia/images/property/import/539/2609539/0e76b9541118d347871c0e0e51d244c4/388d88b8f2d0b8749f032c021dd8647d/ORIGINAL.jpeg | R14: false | S14: false | T14: 60.62213 | U14: 2609539 | V14: https://www.etuovi.com/kohde/80505512 | W14: 24.84667 | X14: 58000 | Y14: 58 000 € | AA14: Apartment (Kerrostalo) | AB14: RESIDENTIAL | AC14: 2026-06-10 | AD14: 1 | AE14: 1h, k | AF14: 2026-06-10T14:03:15.750Z | AG14: Apartment (Kerrostalo) — 1h, k — 42 m² — Kirjavatolppa Hyvinkää | AH14: 42 | AI14: =IF(AE14="", "no info", IF(OR(ISNUMBER(SEARCH("kt", AE14)), ISNUMBER(SEARCH("avokeittiö", AE14))), "Open", IF(ISNUMBER(SEARCH("kk", AE14)), "Kitchenette", "Independent"))) -> Independent | AJ14: =IF(AE14="", "no info", IF(OR(ISNUMBER(SEARCH(" s ", AE14)), ISNUMBER(SEARCH("sauna", AE14)), ISNUMBER(SEARCH("+ s", AE14))), "YES", "NO")) -> NO | AK14: =IF(AE14="", "no info", IF(OR(ISNUMBER(SEARCH("las.p", AE14)), ISNUMBER(SEARCH("lasitettu", AE14))), "Glazed Balcony", IF(OR(ISNUMBER(SEARCH(" p ", AE14)), ISNUMBER(SEARCH("parveke", AE14))), "Standard Balcony", IF(OR(ISNUMBER(SEARCH("terassi", AE14)), ISNUMBER(SEARCH("kuisti", AE14))), "Terrace", "None")))) -> None | AL14: =IF(AE14="", "no info", IF(OR(ISNUMBER(SEARCH("2wc", AE14)), ISNUMBER(SEARCH("2xwc", AE14))), "2 Toilets", "1 Toilet")) -> 1 Toilet | AM14: =IF(AE14="", "no info", IF(OR(ISNUMBER(SEARCH("vh", AE14)), ISNUMBER(SEARCH("var", AE14))), "YES", "NO")) -> NO | AN14: =VLOOKUP(J14, 'Regions and Cities'!A:B, 2, FALSE) -> Uusimaa
A15: Ajurintie 6 as Taatila Lieto | B15: Ajurintie 6 as | C15: Taatila Lieto | D15: 641 | E15: REMAX OmaanKotiin | Kiinteistönvälitys OmaanKotiin Oy LKV | F15: https://www.remax.fi/ | G15: Milla Survo | H15: 54 | I15: 2016 | J15: Lieto | K15: Taatila | L15: 80508573 | M15: false | N15: https://d3ls91xgksobn.cloudfront.net/400x300/etuovimedia/images/property/import/701/2608701/0e76b9541118d347871c0e0e51d244c4/fe9c8c1477876f0daf67a32f564e633b/ORIGINAL.jpeg | O15: https://d3ls91xgksobn.cloudfront.net/1200x900/etuovimedia/images/property/import/701/2608701/0e76b9541118d347871c0e0e51d244c4/fe9c8c1477876f0daf67a32f564e633b/ORIGINAL.jpeg | P15: https://d3ls91xgksobn.cloudfront.net/1200x900/etuovimedia/images/property/import/701/2608701/0e76b9541118d347871c0e0e51d244c4/cc1921326ca404d303742167e78fc336/ORIGINAL.jpeg | R15: false | S15: false | T15: 60.50166 | U15: 2608701 | V15: https://www.etuovi.com/kohde/80508573 | W15: 22.46126 | X15: 179000 | Y15: 179 000 € | AA15: Apartment (Kerrostalo) | AB15: RESIDENTIAL | AC15: 2026-06-09 | AD15: 2 | AE15: 2h + k + s + vh + lasitettu parveke | AF15: 2026-06-10T14:04:25.183Z | AG15: Apartment (Kerrostalo) — 2h + k + s + vh + lasitettu parveke — 54 m² — Taatila Lieto | AH15: 54 | AI15: =IF(AE15="", "no info", IF(OR(ISNUMBER(SEARCH("kt", AE15)), ISNUMBER(SEARCH("avokeittiö", AE15))), "Open", IF(ISNUMBER(SEARCH("kk", AE15)), "Kitchenette", "Independent"))) -> Independent | AJ15: =IF(AE15="", "no info", IF(OR(ISNUMBER(SEARCH(" s ", AE15)), ISNUMBER(SEARCH("sauna", AE15)), ISNUMBER(SEARCH("+ s", AE15))), "YES", "NO")) -> YES | AK15: =IF(AE15="", "no info", IF(OR(ISNUMBER(SEARCH("las.p", AE15)), ISNUMBER(SEARCH("lasitettu", AE15))), "Glazed Balcony", IF(OR(ISNUMBER(SEARCH(" p ", AE15)), ISNUMBER(SEARCH("parveke", AE15))), "Standard Balcony", IF(OR(ISNUMBER(SEARCH("terassi", AE15)), ISNUMBER(SEARCH("kuisti", AE15))), "Terrace", "None")))) -> Glazed Balcony | AL15: =IF(AE15="", "no info", IF(OR(ISNUMBER(SEARCH("2wc", AE15)), ISNUMBER(SEARCH("2xwc", AE15))), "2 Toilets", "1 Toilet")) -> 1 Toilet | AM15: =IF(AE15="", "no info", IF(OR(ISNUMBER(SEARCH("vh", AE15)), ISNUMBER(SEARCH("var", AE15))), "YES", "NO")) -> YES | AN15: =VLOOKUP(J15, 'Regions and Cities'!A:B, 2, FALSE) -> Varsinais-Suomi
A16: Alakatu 10 Hamina Ii | B16: Alakatu 10 | C16: Hamina Ii | D16: 3164 | E16: OP Koti Pohjoinen Oy LKV, Oulu | F16: https://op-koti.fi?cmpid=.opkoti..huom.1.etuovi.banner.yrityslogo.ha_jn_opkoti_valitys | G16: Oskari Rounaja | H16: 114.1 | I16: 1920 | J16: Ii | K16: Hamina | L16: 617232 | M16: false | N16: https://d3ls91xgksobn.cloudfront.net/400x300/etuovimedia/images/property/import/758/2543758/0e76b9541118d347871c0e0e51d244c4/772f36060c196fd7ca70bf82c4176fce/ORIGINAL.jpeg | O16: https://d3ls91xgksobn.cloudfront.net/1200x900/etuovimedia/images/property/import/758/2543758/0e76b9541118d347871c0e0e51d244c4/772f36060c196fd7ca70bf82c4176fce/ORIGINAL.jpeg | P16: https://d3ls91xgksobn.cloudfront.net/1200x900/etuovimedia/images/property/import/758/2543758/0e76b9541118d347871c0e0e51d244c4/cddc35b76175bf913a70f7dd51545e67/ORIGINAL.jpeg | Q16: https://d3ls91xgksobn.cloudfront.net/1200x900/etuovimedia/images/property/import/758/2543758/0e76b9541118d347871c0e0e51d244c4/def1795c731487039f28085c36afcbf9/ORIGINAL.jpeg | R16: false | S16: false | T16: 65.325361 | U16: 2543758 | V16: https://www.etuovi.com/kohde/617232 | W16: 25.370548 | X16: 168000 | Y16: 168 000 € | AA16: Detached House (Omakotitalo) | AB16: RESIDENTIAL | AC16: 2026-04-17 | AD16: 4 | AE16: 4h, k, kph, s, wc | AF16: 2026-06-10T14:04:07.182Z | AG16: Detached House (Omakotitalo) — 4h, k, kph, s, wc — 114.1 m² — Hamina Ii | AH16: 125 | AI16: =IF(AE16="", "no info", IF(OR(ISNUMBER(SEARCH("kt", AE16)), ISNUMBER(SEARCH("avokeittiö", AE16))), "Open", IF(ISNUMBER(SEARCH("kk", AE16)), "Kitchenette", "Independent"))) -> Independent | AJ16: =IF(AE16="", "no info", IF(OR(ISNUMBER(SEARCH(" s ", AE16)), ISNUMBER(SEARCH("sauna", AE16)), ISNUMBER(SEARCH("+ s", AE16))), "YES", "NO")) -> NO | AK16: =IF(AE16="", "no info", IF(OR(ISNUMBER(SEARCH("las.p", AE16)), ISNUMBER(SEARCH("lasitettu", AE16))), "Glazed Balcony", IF(OR(ISNUMBER(SEARCH(" p ", AE16)), ISNUMBER(SEARCH("parveke", AE16))), "Standard Balcony", IF(OR(ISNUMBER(SEARCH("terassi", AE16)), ISNUMBER(SEARCH("kuisti", AE16))), "Terrace", "None")))) -> None | AL16: =IF(AE16="", "no info", IF(OR(ISNUMBER(SEARCH("2wc", AE16)), ISNUMBER(SEARCH("2xwc", AE16))), "2 Toilets", "1 Toilet")) -> 1 Toilet | AM16: =IF(AE16="", "no info", IF(OR(ISNUMBER(SEARCH("vh", AE16)), ISNUMBER(SEARCH("var", AE16))), "YES", "NO")) -> NO | AN16: =VLOOKUP(J16, 'Regions and Cities'!A:B, 2, FALSE) -> Pohjois-Pohjanmaa
A17: Alatie 11a Toijala Akaa | B17: Alatie 11a | C17: Toijala Akaa | D17: 3795 | E17: Strand Properties | Tuukka Hakkarainen LKV | F17: https://strandproperties.com/fi/strand-suomi/ | G17: Hakkarainen Tuukka | H17: 113 | I17: 2021 | J17: Akaa | K17: Toijala | L17: 21225556 | M17: false | N17: https://d3ls91xgksobn.cloudfront.net/400x300/etuovimedia/images/property/import/758/2571758/0e76b9541118d347871c0e0e51d244c4/f975a81a02b6cf80211dbc03fb2e826f/ORIGINAL.jpeg | O17: https://d3ls91xgksobn.cloudfront.net/1200x900/etuovimedia/images/property/import/758/2571758/0e76b9541118d347871c0e0e51d244c4/f975a81a02b6cf80211dbc03fb2e826f/ORIGINAL.jpeg | P17: https://d3ls91xgksobn.cloudfront.net/1200x900/etuovimedia/images/property/import/758/2571758/0e76b9541118d347871c0e0e51d244c4/31c24d825f232fbb6abb3581655bd331/ORIGINAL.jpeg | R17: false | S17: false | T17: 61.163482 | U17: 2571758 | V17: https://www.etuovi.com/kohde/21225556 | W17: 23.850696 | X17: 319000 | Y17: 319 000 € | AA17: Detached House (Omakotitalo) | AB17: RESIDENTIAL | AC17: 2026-05-09 | AD17: 5 | AE17: 4mh, oh, k, ph, s, khh, autokatos | AF17: 2026-06-10T14:03:46.761Z | AG17: Detached House (Omakotitalo) — 4mh, oh, k, ph, s, khh, autokatos — 113 m² — Toijala Akaa | AH17: 125 | AI17: =IF(AE17="", "no info", IF(OR(ISNUMBER(SEARCH("kt", AE17)), ISNUMBER(SEARCH("avokeittiö", AE17))), "Open", IF(ISNUMBER(SEARCH("kk", AE17)), "Kitchenette", "Independent"))) -> Independent | AJ17: =IF(AE17="", "no info", IF(OR(ISNUMBER(SEARCH(" s ", AE17)), ISNUMBER(SEARCH("sauna", AE17)), ISNUMBER(SEARCH("+ s", AE17))), "YES", "NO")) -> NO | AK17: =IF(AE17="", "no info", IF(OR(ISNUMBER(SEARCH("las.p", AE17)), ISNUMBER(SEARCH("lasitettu", AE17))), "Glazed Balcony", IF(OR(ISNUMBER(SEARCH(" p ", AE17)), ISNUMBER(SEARCH("parveke", AE17))), "Standard Balcony", IF(OR(ISNUMBER(SEARCH("terassi", AE17)), ISNUMBER(SEARCH("kuisti", AE17))), "Terrace", "None")))) -> None | AL17: =IF(AE17="", "no info", IF(OR(ISNUMBER(SEARCH("2wc", AE17)), ISNUMBER(SEARCH("2xwc", AE17))), "2 Toilets", "1 Toilet")) -> 1 Toilet | AM17: =IF(AE17="", "no info", IF(OR(ISNUMBER(SEARCH("vh", AE17)), ISNUMBER(SEARCH("var", AE17))), "YES", "NO")) -> NO | AN17: =VLOOKUP(J17, 'Regions and Cities'!A:B, 2, FALSE) -> Pirkanmaa
A18: Albertinkuja 20 B Keskusta Oulu | B18: Albertinkuja 20 B | C18: Keskusta Oulu | D18: 3164 | E18: OP Koti Pohjoinen Oy LKV, Oulu | F18: https://op-koti.fi?cmpid=.opkoti..huom.1.etuovi.banner.yrityslogo.ha_jn_opkoti_valitys | G18: Terhi Heikkilä | H18: 78 | I18: 2018 | J18: Oulu | K18: Keskusta | L18: 620395 | M18: false | N18: https://d3ls91xgksobn.cloudfront.net/400x300/etuovimedia/images/property/import/423/2609423/0e76b9541118d347871c0e0e51d244c4/826729b23683b38db480cdbcf7f0d2db/ORIGINAL.jpeg | O18: https://d3ls91xgksobn.cloudfront.net/1200x900/etuovimedia/images/property/import/423/2609423/0e76b9541118d347871c0e0e51d244c4/826729b23683b38db480cdbcf7f0d2db/ORIGINAL.jpeg | P18: https://d3ls91xgksobn.cloudfront.net/1200x900/etuovimedia/images/property/import/423/2609423/0e76b9541118d347871c0e0e51d244c4/967ca0fbd2ff5f51e0ffb7656a1a235c/ORIGINAL.jpeg | R18: false | S18: false | T18: 65.008583 | U18: 2609423 | V18: https://www.etuovi.com/kohde/620395 | W18: 25.472414 | X18: 393000 | Y18: 393 000 € | AA18: Apartment (Kerrostalo) | AB18: RESIDENTIAL | AC18: 2026-06-10 | AD18: 3 | AE18: 3h, k, ru, s | AF18: 2026-06-10T14:03:26.763Z | AG18: Apartment (Kerrostalo) — 3h, k, ru, s — 78 m² — Keskusta Oulu | AH18: 78 | AI18: =IF(AE18="", "no info", IF(OR(ISNUMBER(SEARCH("kt", AE18)), ISNUMBER(SEARCH("avokeittiö", AE18))), "Open", IF(ISNUMBER(SEARCH("kk", AE18)), "Kitchenette", "Independent"))) -> Independent | AJ18: =IF(AE18="", "no info", IF(OR(ISNUMBER(SEARCH(" s ", AE18)), ISNUMBER(SEARCH("sauna", AE18)), ISNUMBER(SEARCH("+ s", AE18))), "YES", "NO")) -> NO | AK18: =IF(AE18="", "no info", IF(OR(ISNUMBER(SEARCH("las.p", AE18)), ISNUMBER(SEARCH("lasitettu", AE18))), "Glazed Balcony", IF(OR(ISNUMBER(SEARCH(" p ", AE18)), ISNUMBER(SEARCH("parveke", AE18))), "Standard Balcony", IF(OR(ISNUMBER(SEARCH("terassi", AE18)), ISNUMBER(SEARCH("kuisti", AE18))), "Terrace", "None")))) -> None | AL18: =IF(AE18="", "no info", IF(OR(ISNUMBER(SEARCH("2wc", AE18)), ISNUMBER(SEARCH("2xwc", AE18))), "2 Toilets", "1 Toilet")) -> 1 Toilet | AM18: =IF(AE18="", "no info", IF(OR(ISNUMBER(SEARCH("vh", AE18)), ISNUMBER(SEARCH("var", AE18))), "YES", "NO")) -> NO | AN18: =VLOOKUP(J18, 'Regions and Cities'!A:B, 2, FALSE) -> Pohjois-Pohjanmaa
A19: Albininkatu 1 B Kärki Seinäjoki | B19: Albininkatu 1 B | C19: Kärki Seinäjoki | D19: 605 | E19: OP Koti Etelä-Pohjanmaa Oy LKV | F19: https://op-koti.fi?cmpid=.opkoti..huom.1.etuovi.banner.yrityslogo.ha_jn_opkoti_valitys | G19: Linda Mäkivirta-Valkama | H19: 63 | I19: 2015 | J19: Seinäjoki | K19: Kärki | L19: 614909 | M19: false | N19: https://d3ls91xgksobn.cloudfront.net/400x300/etuovimedia/images/property/import/516/2500516/0e76b9541118d347871c0e0e51d244c4/d7125741480f3cf6f79603e70085df86/ORIGINAL.jpeg | O19: https://d3ls91xgksobn.cloudfront.net/1200x900/etuovimedia/images/property/import/516/2500516/0e76b9541118d347871c0e0e51d244c4/d7125741480f3cf6f79603e70085df86/ORIGINAL.jpeg | P19: https://d3ls91xgksobn.cloudfront.net/1200x900/etuovimedia/images/property/import/516/2500516/0e76b9541118d347871c0e0e51d244c4/d6dcddeca2083483e6c5c15d5d3e2f52/ORIGINAL.jpeg | Q19: https://d3ls91xgksobn.cloudfront.net/1200x900/etuovimedia/images/property/import/516/2500516/0e76b9541118d347871c0e0e51d244c4/cc006dbdcd163b80f1849cbf6fd1dde6/ORIGINAL.jpeg | R19: false | S19: false | T19: 62.740527 | U19: 2500516 | V19: https://www.etuovi.com/kohde/614909 | W19: 22.871635 | X19: 160000 | Y19: 160 000 € | AA19: Row House (Rivitalo) | AB19: RESIDENTIAL | AC19: 2026-03-09 | AD19: 3 | AE19: 3h + k + s | AF19: 2026-06-10T14:03:17.202Z | AG19: Row House (Rivitalo) — 3h + k + s — 63 m² — Kärki Seinäjoki | AH19: 63 | AI19: =IF(AE19="", "no info", IF(OR(ISNUMBER(SEARCH("kt", AE19)), ISNUMBER(SEARCH("avokeittiö", AE19))), "Open", IF(ISNUMBER(SEARCH("kk", AE19)), "Kitchenette", "Independent"))) -> Independent | AJ19: =IF(AE19="", "no info", IF(OR(ISNUMBER(SEARCH(" s ", AE19)), ISNUMBER(SEARCH("sauna", AE19)), ISNUMBER(SEARCH("+ s", AE19))), "YES", "NO")) -> YES | AK19: =IF(AE19="", "no info", IF(OR(ISNUMBER(SEARCH("las.p", AE19)), ISNUMBER(SEARCH("lasitettu", AE19))), "Glazed Balcony", IF(OR(ISNUMBER(SEARCH(" p ", AE19)), ISNUMBER(SEARCH("parveke", AE19))), "Standard Balcony", IF(OR(ISNUMBER(SEARCH("terassi", AE19)), ISNUMBER(SEARCH("kuisti", AE19))), "Terrace", "None")))) -> None | AL19: =IF(AE19="", "no info", IF(OR(ISNUMBER(SEARCH("2wc", AE19)), ISNUMBER(SEARCH("2xwc", AE19))), "2 Toilets", "1 Toilet")) -> 1 Toilet | AM19: =IF(AE19="", "no info", IF(OR(ISNUMBER(SEARCH("vh", AE19)), ISNUMBER(SEARCH("var", AE19))), "YES", "NO")) -> NO | AN19: =VLOOKUP(J19, 'Regions and Cities'!A:B, 2, FALSE) -> Etelä-Pohjanmaa
A20: Aleksinpolku 6 A 34 Länsiranta Porvoo | B20: Aleksinpolku 6 A 34 | C20: Länsiranta Porvoo | D20: 3592 | E20: Blok | Magenta Homes Oy | H20: 50 | I20: 2021 | J20: Porvoo | K20: Länsiranta | L20: fd8923 | M20: false | N20: https://d3ls91xgksobn.cloudfront.net/400x300/etuovimedia/images/property/import/547/2565547/0e76b9541118d347871c0e0e51d244c4/52a0603a391251990661160ed50bcdb3/ORIGINAL.jpeg | O20: https://d3ls91xgksobn.cloudfront.net/1200x900/etuovimedia/images/property/import/547/2565547/0e76b9541118d347871c0e0e51d244c4/52a0603a391251990661160ed50bcdb3/ORIGINAL.jpeg | R20: false | S20: false | T20: 60.38948 | U20: 2565547 | V20: https://www.etuovi.com/kohde/fd8923 | W20: 25.65754 | X20: 209000 | Y20: 209 000 € | AA20: Apartment (Kerrostalo) | AB20: RESIDENTIAL | AC20: 2026-05-05 | AD20: 2 | AE20: 2h + avok + kph + s + las.parv | AF20: 2026-06-10T14:04:10.751Z | AG20: Apartment (Kerrostalo) — 2h + avok + kph + s + las.parv — 50 m² — Länsiranta Porvoo | AH20: 50 | AI20: =IF(AE20="", "no info", IF(OR(ISNUMBER(SEARCH("kt", AE20)), ISNUMBER(SEARCH("avokeittiö", AE20))), "Open", IF(ISNUMBER(SEARCH("kk", AE20)), "Kitchenette", "Independent"))) -> Independent | AJ20: =IF(AE20="", "no info", IF(OR(ISNUMBER(SEARCH(" s ", AE20)), ISNUMBER(SEARCH("sauna", AE20)), ISNUMBER(SEARCH("+ s", AE20))), "YES", "NO")) -> YES | AK20: =IF(AE20="", "no info", IF(OR(ISNUMBER(SEARCH("las.p", AE20)), ISNUMBER(SEARCH("lasitettu", AE20))), "Glazed Balcony", IF(OR(ISNUMBER(SEARCH(" p ", AE20)), ISNUMBER(SEARCH("parveke", AE20))), "Standard Balcony", IF(OR(ISNUMBER(SEARCH("terassi", AE20)), ISNUMBER(SEARCH("kuisti", AE20))), "Terrace", "None")))) -> Glazed Balcony | AL20: =IF(AE20="", "no info", IF(OR(ISNUMBER(SEARCH("2wc", AE20)), ISNUMBER(SEARCH("2xwc", AE20))), "2 Toilets", "1 Toilet")) -> 1 Toilet | AM20: =IF(AE20="", "no info", IF(OR(ISNUMBER(SEARCH("vh", AE20)), ISNUMBER(SEARCH("var", AE20))), "YES", "NO")) -> NO | AN20: =VLOOKUP(J20, 'Regions and Cities'!A:B, 2, FALSE) -> Uusimaa
A21: Aleksintie 1 As Kärsämäki | B21: Aleksintie 1 As | C21: Kärsämäki | D21: 982 | E21: Kiinteistönvälitys Keidas LKV Oy / Nivala | F21: http://www.kiinteistokeidas.fi/ | H21: 65 | J21: Kärsämäki | L21: 80509181 | M21: false | N21: https://d3ls91xgksobn.cloudfront.net/400x300/etuovimedia/images/property/import/533/2608533/0e76b9541118d347871c0e0e51d244c4/7fdee3d0ba3d50f677fb5bf338e77104/ORIGINAL.jpeg | O21: https://d3ls91xgksobn.cloudfront.net/1200x900/etuovimedia/images/property/import/533/2608533/0e76b9541118d347871c0e0e51d244c4/7fdee3d0ba3d50f677fb5bf338e77104/ORIGINAL.jpeg | R21: false | S21: false | T21: 63.98062 | U21: 2608533 | V21: https://www.etuovi.com/kohde/80509181 | W21: 25.76058 | X21: 16000 | Y21: 16 000 € | AA21: Apartment (Kerrostalo) | AB21: RESIDENTIAL | AC21: 2026-06-09 | AD21: 2 | AE21: Oh + k + mh + ph + s + et + tk + vh | AF21: 2026-06-10T14:04:41.950Z | AG21: Apartment (Kerrostalo) — Oh + k + mh + ph + s + et + tk + vh — 65 m² — Kärsämäki | AH21: 65 | AI21: =IF(AE21="", "no info", IF(OR(ISNUMBER(SEARCH("kt", AE21)), ISNUMBER(SEARCH("avokeittiö", AE21))), "Open", IF(ISNUMBER(SEARCH("kk", AE21)), "Kitchenette", "Independent"))) -> Independent | AJ21: =IF(AE21="", "no info", IF(OR(ISNUMBER(SEARCH(" s ", AE21)), ISNUMBER(SEARCH("sauna", AE21)), ISNUMBER(SEARCH("+ s", AE21))), "YES", "NO")) -> YES | AK21: =IF(AE21="", "no info", IF(OR(ISNUMBER(SEARCH("las.p", AE21)), ISNUMBER(SEARCH("lasitettu", AE21))), "Glazed Balcony", IF(OR(ISNUMBER(SEARCH(" p ", AE21)), ISNUMBER(SEARCH("parveke", AE21))), "Standard Balcony", IF(OR(ISNUMBER(SEARCH("terassi", AE21)), ISNUMBER(SEARCH("kuisti", AE21))), "Terrace", "None")))) -> None | AL21: =IF(AE21="", "no info", IF(OR(ISNUMBER(SEARCH("2wc", AE21)), ISNUMBER(SEARCH("2xwc", AE21))), "2 Toilets", "1 Toilet")) -> 1 Toilet | AM21: =IF(AE21="", "no info", IF(OR(ISNUMBER(SEARCH("vh", AE21)), ISNUMBER(SEARCH("var", AE21))), "YES", "NO")) -> YES | AN21: =VLOOKUP(J21, 'Regions and Cities'!A:B, 2, FALSE) -> Pohjois-Pohjanmaa
A22: Alhonkatu 21 B Rauhala Kotka | B22: Alhonkatu 21 B | C22: Rauhala Kotka | D22: 3293 | E22: Aitoa LKV | Aitoa välittämistä Oy | F22: http://www.aitoalkv.fi/ | H22: 85 | I22: 1994 | J22: Kotka | K22: Rauhala | L22: 80514044 | M22: false | N22: https://d3ls91xgksobn.cloudfront.net/400x300/etuovimedia/images/property/import/957/2608957/0e76b9541118d347871c0e0e51d244c4/cb3a9e708d03525f3ee97b9aaa2fea15/ORIGINAL.jpeg | O22: https://d3ls91xgksobn.cloudfront.net/1200x900/etuovimedia/images/property/import/957/2608957/0e76b9541118d347871c0e0e51d244c4/cb3a9e708d03525f3ee97b9aaa2fea15/ORIGINAL.jpeg | R22: false | S22: false | T22: 60.513 | U22: 2608957 | V22: https://www.etuovi.com/kohde/80514044 | W22: 26.95546 | X22: 145000 | Y22: 145 000 € | AA22: Semi-detached (Paritalo) | AB22: RESIDENTIAL | AC22: 2026-06-10 | AD22: 4 | AE22: 4h + k + kph + s + khh + ak + varasto + piha + patio | AF22: 2026-06-10T14:04:07.751Z | AG22: Semi-detached (Paritalo) — 4h + k + kph + s + khh + ak + varasto + piha + patio — 85 m² — Rauhala Kotka | AH22: 85 | AI22: =IF(AE22="", "no info", IF(OR(ISNUMBER(SEARCH("kt", AE22)), ISNUMBER(SEARCH("avokeittiö", AE22))), "Open", IF(ISNUMBER(SEARCH("kk", AE22)), "Kitchenette", "Independent"))) -> Independent | AJ22: =IF(AE22="", "no info", IF(OR(ISNUMBER(SEARCH(" s ", AE22)), ISNUMBER(SEARCH("sauna", AE22)), ISNUMBER(SEARCH("+ s", AE22))), "YES", "NO")) -> YES | AK22: =IF(AE22="", "no info", IF(OR(ISNUMBER(SEARCH("las.p", AE22)), ISNUMBER(SEARCH("lasitettu", AE22))), "Glazed Balcony", IF(OR(ISNUMBER(SEARCH(" p ", AE22)), ISNUMBER(SEARCH("parveke", AE22))), "Standard Balcony", IF(OR(ISNUMBER(SEARCH("terassi", AE22)), ISNUMBER(SEARCH("kuisti", AE22))), "Terrace", "None")))) -> None | AL22: =IF(AE22="", "no info", IF(OR(ISNUMBER(SEARCH("2wc", AE22)), ISNUMBER(SEARCH("2xwc", AE22))), "2 Toilets", "1 Toilet")) -> 1 Toilet | AM22: =IF(AE22="", "no info", IF(OR(ISNUMBER(SEARCH("vh", AE22)), ISNUMBER(SEARCH("var", AE22))), "YES", "NO")) -> YES | AN22: =VLOOKUP(J22, 'Regions and Cities'!A:B, 2, FALSE) -> Kymenlaakso
A23: Alikyläntie 85 Ruosniemi Pori | B23: Alikyläntie 85 | C23: Ruosniemi Pori | D23: 3836 | E23: Tilanne LKV | Lännen Kiinteistönvälitys Oy | F23: https://www.tilannelkv.fi/ | G23: Ville Kippasto | H23: 106 | I23: 2024 | J23: Pori | K23: Ruosniemi | L23: 55774473 | M23: false | N23: https://d3ls91xgksobn.cloudfront.net/400x300/etuovimedia/images/property/import/557/2608557/0e76b9541118d347871c0e0e51d244c4/1c967f7c9fab3b069107b9368c2eac41/ORIGINAL.jpeg | O23: https://d3ls91xgksobn.cloudfront.net/1200x900/etuovimedia/images/property/import/557/2608557/0e76b9541118d347871c0e0e51d244c4/1c967f7c9fab3b069107b9368c2eac41/ORIGINAL.jpeg | P23: https://d3ls91xgksobn.cloudfront.net/1200x900/etuovimedia/images/property/import/557/2608557/0e76b9541118d347871c0e0e51d244c4/46a292b69e36d2e8f6257785f77e7b8d/ORIGINAL.jpeg | R23: true | S23: false | T23: 61.518953 | U23: 2608557 | V23: https://www.etuovi.com/kohde/55774473 | W23: 21.840223 | X23: 289000 | Y23: 289 000 € | AA23: Detached House (Omakotitalo) | AB23: RESIDENTIAL | AC23: 2026-06-09 | AD23: 4 | AE23: 4h, tupak, kph, s, khh, wc, vh, terassi, var, ak | AF23: 2026-06-10T14:04:35.464Z | AG23: Detached House (Omakotitalo) — 4h, tupak, kph, s, khh, wc, vh, terassi, var, ak — 106 m² — Ruosniemi Pori | AH23: 135 | AI23: =IF(AE23="", "no info", IF(OR(ISNUMBER(SEARCH("kt", AE23)), ISNUMBER(SEARCH("avokeittiö", AE23))), "Open", IF(ISNUMBER(SEARCH("kk", AE23)), "Kitchenette", "Independent"))) -> Independent | AJ23: =IF(AE23="", "no info", IF(OR(ISNUMBER(SEARCH(" s ", AE23)), ISNUMBER(SEARCH("sauna", AE23)), ISNUMBER(SEARCH("+ s", AE23))), "YES", "NO")) -> NO | AK23: =IF(AE23="", "no info", IF(OR(ISNUMBER(SEARCH("las.p", AE23)), ISNUMBER(SEARCH("lasitettu", AE23))), "Glazed Balcony", IF(OR(ISNUMBER(SEARCH(" p ", AE23)), ISNUMBER(SEARCH("parveke", AE23))), "Standard Balcony", IF(OR(ISNUMBER(SEARCH("terassi", AE23)), ISNUMBER(SEARCH("kuisti", AE23))), "Terrace", "None")))) -> Terrace | AL23: =IF(AE23="", "no info", IF(OR(ISNUMBER(SEARCH("2wc", AE23)), ISNUMBER(SEARCH("2xwc", AE23))), "2 Toilets", "1 Toilet")) -> 1 Toilet | AM23: =IF(AE23="", "no info", IF(OR(ISNUMBER(SEARCH("vh", AE23)), ISNUMBER(SEARCH("var", AE23))), "YES", "NO")) -> YES | AN23: =VLOOKUP(J23, 'Regions and Cities'!A:B, 2, FALSE) -> Satakunta
A24: Alppijääkärintie 13 Petäjäkangas Kuusamo | B24: Alppijääkärintie 13 | C24: Petäjäkangas Kuusamo | D24: 789 | E24: Kiinteistönvälitys LKV Saaga Oy | F24: https://lkvsaaga.fi/ | H24: 136 | I24: 1984 | J24: Kuusamo | K24: Petäjäkangas | L24: 20017029 | M24: false | N24: https://d3ls91xgksobn.cloudfront.net/400x300/etuovimedia/images/property/import/234/2608234/0e76b9541118d347871c0e0e51d244c4/fdcdb00846fb1c082af3291203396db7/ORIGINAL.jpeg | O24: https://d3ls91xgksobn.cloudfront.net/1200x900/etuovimedia/images/property/import/234/2608234/0e76b9541118d347871c0e0e51d244c4/fdcdb00846fb1c082af3291203396db7/ORIGINAL.jpeg | R24: false | S24: false | T24: 65.992964 | U24: 2608234 | V24: https://www.etuovi.com/kohde/20017029 | W24: 29.175608 | X24: 139000 | Y24: 139 000 € | AA24: Detached House (Omakotitalo) | AB24: RESIDENTIAL | AC24: 2026-06-09 | AD24: 5 | AE24: 5h + khh + k + s | AF24: 2026-06-10T14:05:05.749Z | AG24: Detached House (Omakotitalo) — 5h + khh + k + s — 136 m² — Petäjäkangas Kuusamo | AH24: 183 | AI24: =IF(AE24="", "no info", IF(OR(ISNUMBER(SEARCH("kt", AE24)), ISNUMBER(SEARCH("avokeittiö", AE24))), "Open", IF(ISNUMBER(SEARCH("kk", AE24)), "Kitchenette", "Independent"))) -> Independent | AJ24: =IF(AE24="", "no info", IF(OR(ISNUMBER(SEARCH(" s ", AE24)), ISNUMBER(SEARCH("sauna", AE24)), ISNUMBER(SEARCH("+ s", AE24))), "YES", "NO")) -> YES | AK24: =IF(AE24="", "no info", IF(OR(ISNUMBER(SEARCH("las.p", AE24)), ISNUMBER(SEARCH("lasitettu", AE24))), "Glazed Balcony", IF(OR(ISNUMBER(SEARCH(" p ", AE24)), ISNUMBER(SEARCH("parveke", AE24))), "Standard Balcony", IF(OR(ISNUMBER(SEARCH("terassi", AE24)), ISNUMBER(SEARCH("kuisti", AE24))), "Terrace", "None")))) -> None | AL24: =IF(AE24="", "no info", IF(OR(ISNUMBER(SEARCH("2wc", AE24)), ISNUMBER(SEARCH("2xwc", AE24))), "2 Toilets", "1 Toilet")) -> 1 Toilet | AM24: =IF(AE24="", "no info", IF(OR(ISNUMBER(SEARCH("vh", AE24)), ISNUMBER(SEARCH("var", AE24))), "YES", "NO")) -> NO | AN24: =VLOOKUP(J24, 'Regions and Cities'!A:B, 2, FALSE) -> Pohjois-Pohjanmaa
A25: Amiraalinkatu 4a Reposaari Pori | B25: Amiraalinkatu 4a | C25: Reposaari Pori | D25: 407 | E25: OP Koti Länsi-Suomi Oy, Pori | F25: https://op-koti.fi?cmpid=.opkoti..huom.1.etuovi.banner.yrityslogo.ha_jn_opkoti_valitys | G25: Miia Kivero | H25: 82 | I25: 1931 | J25: Pori | K25: Reposaari | L25: 620681 | M25: false | N25: https://d3ls91xgksobn.cloudfront.net/400x300/etuovimedia/images/property/import/413/2608413/0e76b9541118d347871c0e0e51d244c4/a2b17448658ca43c737c6b526c0e8a0e/ORIGINAL.jpeg | O25: https://d3ls91xgksobn.cloudfront.net/1200x900/etuovimedia/images/property/import/413/2608413/0e76b9541118d347871c0e0e51d244c4/a2b17448658ca43c737c6b526c0e8a0e/ORIGINAL.jpeg | P25: https://d3ls91xgksobn.cloudfront.net/1200x900/etuovimedia/images/property/import/413/2608413/0e76b9541118d347871c0e0e51d244c4/9b135a7eeba9e75683d300e717b21e61/ORIGINAL.jpeg | Q25: https://d3ls91xgksobn.cloudfront.net/1200x900/etuovimedia/images/property/import/413/2608413/0e76b9541118d347871c0e0e51d244c4/843d399b789684250b9a688d9624e6c7/ORIGINAL.jpeg | R25: false | S25: false | T25: 61.611383 | U25: 2608413 | V25: https://www.etuovi.com/kohde/620681 | W25: 21.446838 | X25: 125000 | Y25: 125 000 € | AA25: Detached House (Omakotitalo) | AB25: RESIDENTIAL | AC25: 2026-06-09 | AD25: 4 | AE25: 4h + k + s | AF25: 2026-06-10T14:04:49.372Z | AG25: Detached House (Omakotitalo) — 4h + k + s — 82 m² — Reposaari Pori | AH25: 82 | AI25: =IF(AE25="", "no info", IF(OR(ISNUMBER(SEARCH("kt", AE25)), ISNUMBER(SEARCH("avokeittiö", AE25))), "Open", IF(ISNUMBER(SEARCH("kk", AE25)), "Kitchenette", "Independent"))) -> Independent | AJ25: =IF(AE25="", "no info", IF(OR(ISNUMBER(SEARCH(" s ", AE25)), ISNUMBER(SEARCH("sauna", AE25)), ISNUMBER(SEARCH("+ s", AE25))), "YES", "NO")) -> YES | AK25: =IF(AE25="", "no info", IF(OR(ISNUMBER(SEARCH("las.p", AE25)), ISNUMBER(SEARCH("lasitettu", AE25))), "Glazed Balcony", IF(OR(ISNUMBER(SEARCH(" p ", AE25)), ISNUMBER(SEARCH("parveke", AE25))), "Standard Balcony", IF(OR(ISNUMBER(SEARCH("terassi", AE25)), ISNUMBER(SEARCH("kuisti", AE25))), "Terrace", "None")))) -> None | AL25: =IF(AE25="", "no info", IF(OR(ISNUMBER(SEARCH("2wc", AE25)), ISNUMBER(SEARCH("2xwc", AE25))), "2 Toilets", "1 Toilet")) -> 1 Toilet | AM25: =IF(AE25="", "no info", IF(OR(ISNUMBER(SEARCH("vh", AE25)), ISNUMBER(SEARCH("var", AE25))), "YES", "NO")) -> NO | AN25: =VLOOKUP(J25, 'Regions and Cities'!A:B, 2, FALSE) -> Satakunta
A26: Anna-kustaavantie 23 Itä-Karttula Kuopio | B26: Anna-kustaavantie 23 | C26: Itä-Karttula Kuopio | D26: 1705 | E26: Sp-Koti | Kallaveden Kiinteistöasiantuntijat Oy LKV | F26: http://www.sp-koti.fi/ | H26: 118.5 | I26: 1988 | J26: Kuopio | K26: Itä-Karttula | L26: 80513599 | M26: false | N26: https://d3ls91xgksobn.cloudfront.net/400x300/etuovimedia/images/property/import/934/2608934/0e76b9541118d347871c0e0e51d244c4/2ae92459ef42c5e5be9b72c3521f38c4/ORIGINAL.jpeg | O26: https://d3ls91xgksobn.cloudfront.net/1200x900/etuovimedia/images/property/import/934/2608934/0e76b9541118d347871c0e0e51d244c4/2ae92459ef42c5e5be9b72c3521f38c4/ORIGINAL.jpeg | R26: false | S26: false | T26: 62.93626 | U26: 2608934 | V26: https://www.etuovi.com/kohde/80513599 | W26: 27.1364 | X26: 79000 | Y26: 79 000 € | AA26: Detached House (Omakotitalo) | AB26: RESIDENTIAL | AC26: 2026-06-10 | AD26: 5 | AE26: 5h, k, kh, s | AF26: 2026-06-10T14:04:10.186Z | AG26: Detached House (Omakotitalo) — 5h, k, kh, s — 118.5 m² — Itä-Karttula Kuopio | AH26: 136 | AI26: =IF(AE26="", "no info", IF(OR(ISNUMBER(SEARCH("kt", AE26)), ISNUMBER(SEARCH("avokeittiö", AE26))), "Open", IF(ISNUMBER(SEARCH("kk", AE26)), "Kitchenette", "Independent"))) -> Independent | AJ26: =IF(AE26="", "no info", IF(OR(ISNUMBER(SEARCH(" s ", AE26)), ISNUMBER(SEARCH("sauna", AE26)), ISNUMBER(SEARCH("+ s", AE26))), "YES", "NO")) -> NO | AK26: =IF(AE26="", "no info", IF(OR(ISNUMBER(SEARCH("las.p", AE26)), ISNUMBER(SEARCH("lasitettu", AE26))), "Glazed Balcony", IF(OR(ISNUMBER(SEARCH(" p ", AE26)), ISNUMBER(SEARCH("parveke", AE26))), "Standard Balcony", IF(OR(ISNUMBER(SEARCH("terassi", AE26)), ISNUMBER(SEARCH("kuisti", AE26))), "Terrace", "None")))) -> None | AL26: =IF(AE26="", "no info", IF(OR(ISNUMBER(SEARCH("2wc", AE26)), ISNUMBER(SEARCH("2xwc", AE26))), "2 Toilets", "1 Toilet")) -> 1 Toilet | AM26: =IF(AE26="", "no info", IF(OR(ISNUMBER(SEARCH("vh", AE26)), ISNUMBER(SEARCH("var", AE26))), "YES", "NO")) -> NO | AN26: =VLOOKUP(J26, 'Regions and Cities'!A:B, 2, FALSE) -> Pohjois-Savo
A27: Antinkatu 21 b B Keskusta Pori | B27: Antinkatu 21 b B | C27: Keskusta Pori | D27: 407 | E27: OP Koti Länsi-Suomi Oy, Pori | F27: https://op-koti.fi?cmpid=.opkoti..huom.1.etuovi.banner.yrityslogo.ha_jn_opkoti_valitys | G27: Jaana Aalto | H27: 38 | I27: 1969 | J27: Pori | K27: Keskusta | L27: 611929 | M27: false | N27: https://d3ls91xgksobn.cloudfront.net/400x300/etuovimedia/images/property/import/221/2447221/0e76b9541118d347871c0e0e51d244c4/95904620591a9d41523434536d99ce25/ORIGINAL.jpeg | O27: https://d3ls91xgksobn.cloudfront.net/1200x900/etuovimedia/images/property/import/221/2447221/0e76b9541118d347871c0e0e51d244c4/95904620591a9d41523434536d99ce25/ORIGINAL.jpeg | P27: https://d3ls91xgksobn.cloudfront.net/1200x900/etuovimedia/images/property/import/221/2447221/0e76b9541118d347871c0e0e51d244c4/ce09df90c15d5d8156bf875a8eda7f5b/ORIGINAL.jpeg | R27: false | S27: false | T27: 61.489532 | U27: 2447221 | V27: https://www.etuovi.com/kohde/611929 | W27: 21.797196 | X27: 59000 | Y27: 59 000 € | AA27: Apartment (Kerrostalo) | AB27: RESIDENTIAL | AC27: 2026-01-16 | AD27: 2 | AE27: 2h, kk, kph, vh | AF27: 2026-06-10T14:03:05.691Z | AG27: Apartment (Kerrostalo) — 2h, kk, kph, vh — 38 m² — Keskusta Pori | AH27: 38 | AI27: =IF(AE27="", "no info", IF(OR(ISNUMBER(SEARCH("kt", AE27)), ISNUMBER(SEARCH("avokeittiö", AE27))), "Open", IF(ISNUMBER(SEARCH("kk", AE27)), "Kitchenette", "Independent"))) -> Kitchenette | AJ27: =IF(AE27="", "no info", IF(OR(ISNUMBER(SEARCH(" s ", AE27)), ISNUMBER(SEARCH("sauna", AE27)), ISNUMBER(SEARCH("+ s", AE27))), "YES", "NO")) -> NO | AK27: =IF(AE27="", "no info", IF(OR(ISNUMBER(SEARCH("las.p", AE27)), ISNUMBER(SEARCH("lasitettu", AE27))), "Glazed Balcony", IF(OR(ISNUMBER(SEARCH(" p ", AE27)), ISNUMBER(SEARCH("parveke", AE27))), "Standard Balcony", IF(OR(ISNUMBER(SEARCH("terassi", AE27)), ISNUMBER(SEARCH("kuisti", AE27))), "Terrace", "None")))) -> None | AL27: =IF(AE27="", "no info", IF(OR(ISNUMBER(SEARCH("2wc", AE27)), ISNUMBER(SEARCH("2xwc", AE27))), "2 Toilets", "1 Toilet")) -> 1 Toilet | AM27: =IF(AE27="", "no info", IF(OR(ISNUMBER(SEARCH("vh", AE27)), ISNUMBER(SEARCH("var", AE27))), "YES", "NO")) -> YES | AN27: =VLOOKUP(J27, 'Regions and Cities'!A:B, 2, FALSE) -> Satakunta
A28: Arhotie 8 a Vartiokylä Helsinki | B28: Arhotie 8 a | C28: Vartiokylä Helsinki | D28: 2274 | E28: Bo LKV Helsinki, Ullanlinna | F28: https://bo.fi/myymassa/ | G28: Roslöf Ronny | H28: 94 | I28: 1953 | J28: Helsinki | K28: Vartiokylä | L28: 20135747 | M28: false | N28: https://d3ls91xgksobn.cloudfront.net/400x300/etuovimedia/images/property/import/866/2608866/0e76b9541118d347871c0e0e51d244c4/507eeb11c350ca7bf99a38ce79225c24/ORIGINAL.jpeg | O28: https://d3ls91xgksobn.cloudfront.net/1200x900/etuovimedia/images/property/import/866/2608866/0e76b9541118d347871c0e0e51d244c4/507eeb11c350ca7bf99a38ce79225c24/ORIGINAL.jpeg | P28: https://d3ls91xgksobn.cloudfront.net/1200x900/etuovimedia/images/property/import/866/2608866/0e76b9541118d347871c0e0e51d244c4/9de82130a480445b9a701fe53995d32d/ORIGINAL.jpeg | R28: false | S28: false | T28: 60.216635 | U28: 2608866 | V28: https://www.etuovi.com/kohde/20135747 | W28: 25.089259 | X28: 369000 | Y28: 369 000 € | AA28: Detached House (Omakotitalo) | AB28: RESIDENTIAL | AC28: 2026-06-10 | AD28: 4 | AE28: 4h, k, kph, erill. wc, khh, at, terassi | AF28: 2026-06-10T14:04:13.609Z | AG28: Detached House (Omakotitalo) — 4h, k, kph, erill. wc, khh, at, terassi — 94 m² — Vartiokylä Helsinki | AH28: 160 | AI28: =IF(AE28="", "no info", IF(OR(ISNUMBER(SEARCH("kt", AE28)), ISNUMBER(SEARCH("avokeittiö", AE28))), "Open", IF(ISNUMBER(SEARCH("kk", AE28)), "Kitchenette", "Independent"))) -> Independent | AJ28: =IF(AE28="", "no info", IF(OR(ISNUMBER(SEARCH(" s ", AE28)), ISNUMBER(SEARCH("sauna", AE28)), ISNUMBER(SEARCH("+ s", AE28))), "YES", "NO")) -> NO | AK28: =IF(AE28="", "no info", IF(OR(ISNUMBER(SEARCH("las.p", AE28)), ISNUMBER(SEARCH("lasitettu", AE28))), "Glazed Balcony", IF(OR(ISNUMBER(SEARCH(" p ", AE28)), ISNUMBER(SEARCH("parveke", AE28))), "Standard Balcony", IF(OR(ISNUMBER(SEARCH("terassi", AE28)), ISNUMBER(SEARCH("kuisti", AE28))), "Terrace", "None")))) -> Terrace | AL28: =IF(AE28="", "no info", IF(OR(ISNUMBER(SEARCH("2wc", AE28)), ISNUMBER(SEARCH("2xwc", AE28))), "2 Toilets", "1 Toilet")) -> 1 Toilet | AM28: =IF(AE28="", "no info", IF(OR(ISNUMBER(SEARCH("vh", AE28)), ISNUMBER(SEARCH("var", AE28))), "YES", "NO")) -> NO | AN28: =VLOOKUP(J28, 'Regions and Cities'!A:B, 2, FALSE) -> Uusimaa
